Workbook

Sheet Loan_Data
A1: Loan_ID | B1: Gender | C1: Married | D1: Dependents | E1: Education | F1: Self_Employed | G1: ApplicantIncome | H1: CoapplicantIncome | I1: LoanAmount | J1: Loan_Amount_Term | K1: Credit_History | L1: Property_Area | M1: Loan_Status | N1: Total_Income | O1: Income_Group | P1: Loan_Status_Label | Q1: Credit_Risk
A2: LP001002 | B2: Male | C2: No | D2: 0 | E2: Graduate | F2: No | G2: 5849 | H2: 0 | I2: 128 | J2: 360 | K2: 1 | L2: Urban | M2: Y | N2: =G2+H2 -> 5849 | O2: =IF(N2<2500,"Low",IF(N2<5000,"Medium",IF(N2<10000,"High","Very High"))) -> High | P2: =IF(M2="Y","Approved","Rejected") -> Approved | Q2: =IF(K2=1,"Low Risk","High Risk") -> Low Risk
A3: LP001003 | B3: Male | C3: Yes | D3: 1 | E3: Graduate | F3: No | G3: 4583 | H3: 1508 | I3: 128 | J3: 360 | K3: 1 | L3: Rural | M3: N | N3: =G3+H3 -> 6091 | O3: =IF(N3<2500,"Low",IF(N3<5000,"Medium",IF(N3<10000,"High","Very High"))) -> High | P3: =IF(M3="Y","Approved","Rejected") -> Rejected | Q3: =IF(K3=1,"Low Risk","High Risk") -> Low Risk
A4: LP001005 | B4: Male | C4: Yes | D4: 0 | E4: Graduate | F4: Yes | G4: 3000 | H4: 0 | I4: 66 | J4: 360 | K4: 1 | L4: Urban | M4: Y | N4: =G4+H4 -> 3000 | O4: =IF(N4<2500,"Low",IF(N4<5000,"Medium",IF(N4<10000,"High","Very High"))) -> Medium | P4: =IF(M4="Y","Approved","Rejected") -> Approved | Q4: =IF(K4=1,"Low Risk","High Risk") -> Low Risk
A5: LP001006 | B5: Male | C5: Yes | D5: 0 | E5: Not Graduate | F5: No | G5: 2583 | H5: 2358 | I5: 120 | J5: 360 | K5: 1 | L5: Urban | M5: Y | N5: =G5+H5 -> 4941 | O5: =IF(N5<2500,"Low",IF(N5<5000,"Medium",IF(N5<10000,"High","Very High"))) -> Medium | P5: =IF(M5="Y","Approved","Rejected") -> Approved | Q5: =IF(K5=1,"Low Risk","High Risk") -> Low Risk
A6: LP001008 | B6: Male | C6: No | D6: 0 | E6: Graduate | F6: No | G6: 6000 | H6: 0 | I6: 141 | J6: 360 | K6: 1 | L6: Urban | M6: Y | N6: =G6+H6 -> 6000 | O6: =IF(N6<2500,"Low",IF(N6<5000,"Medium",IF(N6<10000,"High","Very High"))) -> High | P6: =IF(M6="Y","Approved","Rejected") -> Approved | Q6: =IF(K6=1,"Low Risk","High Risk") -> Low Risk
A7: LP001011 | B7: Male | C7: Yes | D7: 2 | E7: Graduate | F7: Yes | G7: 5417 | H7: 4196 | I7: 267 | J7: 360 | K7: 1 | L7: Urban | M7: Y | N7: =G7+H7 -> 9613 | O7: =IF(N7<2500,"Low",IF(N7<5000,"Medium",IF(N7<10000,"High","Very High"))) -> High | P7: =IF(M7="Y","Approved","Rejected") -> Approved | Q7: =IF(K7=1,"Low Risk","High Risk") -> Low Risk
A8: LP001013 | B8: Male | C8: Yes | D8: 0 | E8: Not Graduate | F8: No | G8: 2333 | H8: 1516 | I8: 95 | J8: 360 | K8: 1 | L8: Urban | M8: Y | N8: =G8+H8 -> 3849 | O8: =IF(N8<2500,"Low",IF(N8<5000,"Medium",IF(N8<10000,"High","Very High"))) -> Medium | P8: =IF(M8="Y","Approved","Rejected") -> Approved | Q8: =IF(K8=1,"Low Risk","High Risk") -> Low Risk
A9: LP001014 | B9: Male | C9: Yes | D9: 3+ | E9: Graduate | F9: No | G9: 3036 | H9: 2504 | I9: 158 | J9: 360 | K9: 0 | L9: Semiurban | M9: N | N9: =G9+H9 -> 5540 | O9: =IF(N9<2500,"Low",IF(N9<5000,"Medium",IF(N9<10000,"High","Very High"))) -> High | P9: =IF(M9="Y","Approved","Rejected") -> Rejected | Q9: =IF(K9=1,"Low Risk","High Risk") -> High Risk
A10: LP001018 | B10: Male | C10: Yes | D10: 2 | E10: Graduate | F10: No | G10: 4006 | H10: 1526 | I10: 168 | J10: 360 | K10: 1 | L10: Urban | M10: Y | N10: =G10+H10 -> 5532 | O10: =IF(N10<2500,"Low",IF(N10<5000,"Medium",IF(N10<10000,"High","Very High"))) -> High | P10: =IF(M10="Y","Approved","Rejected") -> Approved | Q10: =IF(K10=1,"Low Risk","High Risk") -> Low Risk
A11: LP001020 | B11: Male | C11: Yes | D11: 1 | E11: Graduate | F11: No | G11: 12841 | H11: 10968 | I11: 349 | J11: 360 | K11: 1 | L11: Semiurban | M11: N | N11: =G11+H11 -> 23809 | O11: =IF(N11<2500,"Low",IF(N11<5000,"Medium",IF(N11<10000,"High","Very High"))) -> Very High | P11: =IF(M11="Y","Approved","Rejected") -> Rejected | Q11: =IF(K11=1,"Low Risk","High Risk") -> Low Risk
A12: LP001024 | B12: Male | C12: Yes | D12: 2 | E12: Graduate | F12: No | G12: 3200 | H12: 700 | I12: 70 | J12: 360 | K12: 1 | L12: Urban | M12: Y | N12: =G12+H12 -> 3900 | O12: =IF(N12<2500,"Low",IF(N12<5000,"Medium",IF(N12<10000,"High","Very High"))) -> Medium | P12: =IF(M12="Y","Approved","Rejected") -> Approved | Q12: =IF(K12=1,"Low Risk","High Risk") -> Low Risk
A13: LP001027 | B13: Male | C13: Yes | D13: 2 | E13: Graduate | G13: 2500 | H13: 1840 | I13: 109 | J13: 360 | K13: 1 | L13: Urban | M13: Y | N13: =G13+H13 -> 4340 | O13: =IF(N13<2500,"Low",IF(N13<5000,"Medium",IF(N13<10000,"High","Very High"))) -> Medium | P13: =IF(M13="Y","Approved","Rejected") -> Approved | Q13: =IF(K13=1,"Low Risk","High Risk") -> Low Risk
A14: LP001028 | B14: Male | C14: Yes | D14: 2 | E14: Graduate | F14: No | G14: 3073 | H14: 8106 | I14: 200 | J14: 360 | K14: 1 | L14: Urban | M14: Y | N14: =G14+H14 -> 11179 | O14: =IF(N14<2500,"Low",IF(N14<5000,"Medium",IF(N14<10000,"High","Very High"))) -> Very High | P14: =IF(M14="Y","Approved","Rejected") -> Approved | Q14: =IF(K14=1,"Low Risk","High Risk") -> Low Risk
A15: LP001029 | B15: Male | C15: No | D15: 0 | E15: Graduate | F15: No | G15: 1853 | H15: 2840 | I15: 114 | J15: 360 | K15: 1 | L15: Rural | M15: N | N15: =G15+H15 -> 4693 | O15: =IF(N15<2500,"Low",IF(N15<5000,"Medium",IF(N15<10000,"High","Very High"))) -> Medium | P15: =IF(M15="Y","Approved","Rejected") -> Rejected | Q15: =IF(K15=1,"Low Risk","High Risk") -> Low Risk
A16: LP001030 | B16: Male | C16: Yes | D16: 2 | E16: Graduate | F16: No | G16: 1299 | H16: 1086 | I16: 17 | J16: 120 | K16: 1 | L16: Urban | M16: Y | N16: =G16+H16 -> 2385 | O16: =IF(N16<2500,"Low",IF(N16<5000,"Medium",IF(N16<10000,"High","Very High"))) -> Low | P16: =IF(M16="Y","Approved","Rejected") -> Approved | Q16: =IF(K16=1,"Low Risk","High Risk") -> Low Risk
A17: LP001032 | B17: Male | C17: No | D17: 0 | E17: Graduate | F17: No | G17: 4950 | H17: 0 | I17: 125 | J17: 360 | K17: 1 | L17: Urban | M17: Y | N17: =G17+H17 -> 4950 | O17: =IF(N17<2500,"Low",IF(N17<5000,"Medium",IF(N17<10000,"High","Very High"))) -> Medium | P17: =IF(M17="Y","Approved","Rejected") -> Approved | Q17: =IF(K17=1,"Low Risk","High Risk") -> Low Risk
A18: LP001034 | B18: Male | C18: No | D18: 1 | E18: Not Graduate | F18: No | G18: 3596 | H18: 0 | I18: 100 | J18: 240 | K18: 1 | L18: Urban | M18: Y | N18: =G18+H18 -> 3596 | O18: =IF(N18<2500,"Low",IF(N18<5000,"Medium",IF(N18<10000,"High","Very High"))) -> Medium | P18: =IF(M18="Y","Approved","Rejected") -> Approved | Q18: =IF(K18=1,"Low Risk","High Risk") -> Low Risk
A19: LP001036 | B19: Female | C19: No | D19: 0 | E19: Graduate | F19: No | G19: 3510 | H19: 0 | I19: 76 | J19: 360 | K19: 0 | L19: Urban | M19: N | N19: =G19+H19 -> 3510 | O19: =IF(N19<2500,"Low",IF(N19<5000,"Medium",IF(N19<10000,"High","Very High"))) -> Medium | P19: =IF(M19="Y","Approved","Rejected") -> Rejected | Q19: =IF(K19=1,"Low Risk","High Risk") -> High Risk
A20: LP001038 | B20: Male | C20: Yes | D20: 0 | E20: Not Graduate | F20: No | G20: 4887 | H20: 0 | I20: 133 | J20: 360 | K20: 1 | L20: Rural | M20: N | N20: =G20+H20 -> 4887 | O20: =IF(N20<2500,"Low",IF(N20<5000,"Medium",IF(N20<10000,"High","Very High"))) -> Medium | P20: =IF(M20="Y","Approved","Rejected") -> Rejected | Q20: =IF(K20=1,"Low Risk","High Risk") -> Low Risk
A21: LP001041 | B21: Male | C21: Yes | D21: 0 | E21: Graduate | G21: 2600 | H21: 3500 | I21: 115 | J21: 360 | K21: 1 | L21: Urban | M21: Y | N21: =G21+H21 -> 6100 | O21: =IF(N21<2500,"Low",IF(N21<5000,"Medium",IF(N21<10000,"High","Very High"))) -> High | P21: =IF(M21="Y","Approved","Rejected") -> Approved | Q21: =IF(K21=1,"Low Risk","High Risk") -> Low Risk
A22: LP001043 | B22: Male | C22: Yes | D22: 0 | E22: Not Graduate | F22: No | G22: 7660 | H22: 0 | I22: 104 | J22: 360 | K22: 0 | L22: Urban | M22: N | N22: =G22+H22 -> 7660 | O22: =IF(N22<2500,"Low",IF(N22<5000,"Medium",IF(N22<10000,"High","Very High"))) -> High | P22: =IF(M22="Y","Approved","Rejected") -> Rejected | Q22: =IF(K22=1,"Low Risk","High Risk") -> High Risk
A23: LP001046 | B23: Male | C23: Yes | D23: 1 | E23: Graduate | F23: No | G23: 5955 | H23: 5625 | I23: 315 | J23: 360 | K23: 1 | L23: Urban | M23: Y | N23: =G23+H23 -> 11580 | O23: =IF(N23<2500,"Low",IF(N23<5000,"Medium",IF(N23<10000,"High","Very High"))) -> Very High | P23: =IF(M23="Y","Approved","Rejected") -> Approved | Q23: =IF(K23=1,"Low Risk","High Risk") -> Low Risk
A24: LP001047 | B24: Male | C24: Yes | D24: 0 | E24: Not Graduate | F24: No | G24: 2600 | H24: 1911 | I24: 116 | J24: 360 | K24: 0 | L24: Semiurban | M24: N | N24: =G24+H24 -> 4511 | O24: =IF(N24<2500,"Low",IF(N24<5000,"Medium",IF(N24<10000,"High","Very High"))) -> Medium | P24: =IF(M24="Y","Approved","Rejected") -> Rejected | Q24: =IF(K24=1,"Low Risk","High Risk") -> High Risk
A25: LP001050 | B25: Male | C25: Yes | D25: 2 | E25: Not Graduate | F25: No | G25: 3365 | H25: 1917 | I25: 112 | J25: 360 | K25: 0 | L25: Rural | M25: N | N25: =G25+H25 -> 5282 | O25: =IF(N25<2500,"Low",IF(N25<5000,"Medium",IF(N25<10000,"High","Very High"))) -> High | P25: =IF(M25="Y","Approved","Rejected") -> Rejected | Q25: =IF(K25=1,"Low Risk","High Risk") -> High Risk
A26: LP001052 | B26: Male | C26: Yes | D26: 1 | E26: Graduate | G26: 3717 | H26: 2925 | I26: 151 | J26: 360 | K26: 1 | L26: Semiurban | M26: N | N26: =G26+H26 -> 6642 | O26: =IF(N26<2500,"Low",IF(N26<5000,"Medium",IF(N26<10000,"High","Very High"))) -> High | P26: =IF(M26="Y","Approved","Rejected") -> Rejected | Q26: =IF(K26=1,"Low Risk","High Risk") -> Low Risk
A27: LP001066 | B27: Male | C27: Yes | D27: 0 | E27: Graduate | F27: Yes | G27: 9560 | H27: 0 | I27: 191 | J27: 360 | K27: 1 | L27: Semiurban | M27: Y | N27: =G27+H27 -> 9560 | O27: =IF(N27<2500,"Low",IF(N27<5000,"Medium",IF(N27<10000,"High","Very High"))) -> High | P27: =IF(M27="Y","Approved","Rejected") -> Approved | Q27: =IF(K27=1,"Low Risk","High Risk") -> Low Risk
A28: LP001068 | B28: Male | C28: Yes | D28: 0 | E28: Graduate | F28: No | G28: 2799 | H28: 2253 | I28: 122 | J28: 360 | K28: 1 | L28: Semiurban | M28: Y | N28: =G28+H28 -> 5052 | O28: =IF(N28<2500,"Low",IF(N28<5000,"Medium",IF(N28<10000,"High","Very High"))) -> High | P28: =IF(M28="Y","Approved","Rejected") -> Approved | Q28: =IF(K28=1,"Low Risk","High Risk") -> Low Risk
A29: LP001073 | B29: Male | C29: Yes | D29: 2 | E29: Not Graduate | F29: No | G29: 4226 | H29: 1040 | I29: 110 | J29: 360 | K29: 1 | L29: Urban | M29: Y | N29: =G29+H29 -> 5266 | O29: =IF(N29<2500,"Low",IF(N29<5000,"Medium",IF(N29<10000,"High","Very High"))) -> High | P29: =IF(M29="Y","Approved","Rejected") -> Approved | Q29: =IF(K29=1,"Low Risk","High Risk") -> Low Risk
A30: LP001086 | B30: Male | C30: No | D30: 0 | E30: Not Graduate | F30: No | G30: 1442 | H30: 0 | I30: 35 | J30: 360 | K30: 1 | L30: Urban | M30: N | N30: =G30+H30 -> 1442 | O30: =IF(N30<2500,"Low",IF(N30<5000,"Medium",IF(N30<10000,"High","Very High"))) -> Low | P30: =IF(M30="Y","Approved","Rejected") -> Rejected | Q30: =IF(K30=1,"Low Risk","High Risk") -> Low Risk
A31: LP001087 | B31: Female | C31: No | D31: 2 | E31: Graduate | G31: 3750 | H31: 2083 | I31: 120 | J31: 360 | K31: 1 | L31: Semiurban | M31: Y | N31: =G31+H31 -> 5833 | O31: =IF(N31<2500,"Low",IF(N31<5000,"Medium",IF(N31<10000,"High","Very High"))) -> High | P31: =IF(M31="Y","Approved","Rejected") -> Approved | Q31: =IF(K31=1,"Low Risk","High Risk") -> Low Risk
A32: LP001091 | B32: Male | C32: Yes | D32: 1 | E32: Graduate | G32: 4166 | H32: 3369 | I32: 201 | J32: 360 | K32: 1 | L32: Urban | M32: N | N32: =G32+H32 -> 7535 | O32: =IF(N32<2500,"Low",IF(N32<5000,"Medium",IF(N32<10000,"High","Very High"))) -> High | P32: =IF(M32="Y","Approved","Rejected") -> Rejected | Q32: =IF(K32=1,"Low Risk","High Risk") -> Low Risk
A33: LP001095 | B33: Male | C33: No | D33: 0 | E33: Graduate | F33: No | G33: 3167 | H33: 0 | I33: 74 | J33: 360 | K33: 1 | L33: Urban | M33: N | N33: =G33+H33 -> 3167 | O33: =IF(N33<2500,"Low",IF(N33<5000,"Medium",IF(N33<10000,"High","Very High"))) -> Medium | P33: =IF(M33="Y","Approved","Rejected") -> Rejected | Q33: =IF(K33=1,"Low Risk","High Risk") -> Low Risk
A34: LP001097 | B34: Male | C34: No | D34: 1 | E34: Graduate | F34: Yes | G34: 4692 | H34: 0 | I34: 106 | J34: 360 | K34: 1 | L34: Rural | M34: N | N34: =G34+H34 -> 4692 | O34: =IF(N34<2500,"Low",IF(N34<5000,"Medium",IF(N34<10000,"High","Very High"))) -> Medium | P34: =IF(M34="Y","Approved","Rejected") -> Rejected | Q34: =IF(K34=1,"Low Risk","High Risk") -> Low Risk
A35: LP001098 | B35: Male | C35: Yes | D35: 0 | E35: Graduate | F35: No | G35: 3500 | H35: 1667 | I35: 114 | J35: 360 | K35: 1 | L35: Semiurban | M35: Y | N35: =G35+H35 -> 5167 | O35: =IF(N35<2500,"Low",IF(N35<5000,"Medium",IF(N35<10000,"High","Very High"))) -> High | P35: =IF(M35="Y","Approved","Rejected") -> Approved | Q35: =IF(K35=1,"Low Risk","High Risk") -> Low Risk
A36: LP001100 | B36: Male | C36: No | D36: 3+ | E36: Graduate | F36: No | G36: 12500 | H36: 3000 | I36: 320 | J36: 360 | K36: 1 | L36: Rural | M36: N | N36: =G36+H36 -> 15500 | O36: =IF(N36<2500,"Low",IF(N36<5000,"Medium",IF(N36<10000,"High","Very High"))) -> Very High | P36: =IF(M36="Y","Approved","Rejected") -> Rejected | Q36: =IF(K36=1,"Low Risk","High Risk") -> Low Risk
A37: LP001106 | B37: Male | C37: Yes | D37: 0 | E37: Graduate | F37: No | G37: 2275 | H37: 2067 | I37: 128 | J37: 360 | K37: 1 | L37: Urban | M37: Y | N37: =G37+H37 -> 4342 | O37: =IF(N37<2500,"Low",IF(N37<5000,"Medium",IF(N37<10000,"High","Very High"))) -> Medium | P37: =IF(M37="Y","Approved","Rejected") -> Approved | Q37: =IF(K37=1,"Low Risk","High Risk") -> Low Risk
A38: LP001109 | B38: Male | C38: Yes | D38: 0 | E38: Graduate | F38: No | G38: 1828 | H38: 1330 | I38: 100 | J38: 360 | K38: 0 | L38: Urban | M38: N | N38: =G38+H38 -> 3158 | O38: =IF(N38<2500,"Low",IF(N38<5000,"Medium",IF(N38<10000,"High","Very High"))) -> Medium | P38: =IF(M38="Y","Approved","Rejected") -> Rejected | Q38: =IF(K38=1,"Low Risk","High Risk") -> High Risk
A39: LP001112 | B39: Female | C39: Yes | D39: 0 | E39: Graduate | F39: No | G39: 3667 | H39: 1459 | I39: 144 | J39: 360 | K39: 1 | L39: Semiurban | M39: Y | N39: =G39+H39 -> 5126 | O39: =IF(N39<2500,"Low",IF(N39<5000,"Medium",IF(N39<10000,"High","Very High"))) -> High | P39: =IF(M39="Y","Approved","Rejected") -> Approved | Q39: =IF(K39=1,"Low Risk","High Risk") -> Low Risk
A40: LP001114 | B40: Male | C40: No | D40: 0 | E40: Graduate | F40: No | G40: 4166 | H40: 7210 | I40: 184 | J40: 360 | K40: 1 | L40: Urban | M40: Y | N40: =G40+H40 -> 11376 | O40: =IF(N40<2500,"Low",IF(N40<5000,"Medium",IF(N40<10000,"High","Very High"))) -> Very High | P40: =IF(M40="Y","Approved","Rejected") -> Approved | Q40: =IF(K40=1,"Low Risk","High Risk") -> Low Risk
...

Sheet Data_Quality
A1: Column | B1: Missing Count | C1: {=INDEX(Loan_Data!B2:B615,MATCH(MAX(COUNTIF(Loan_Data!B2:B615,Loan_Data!B2:B615)),COUNTIF(Loan_Data!B2:B615,Loan_Data!B2:B615),0))} -> Male | D1: {=MEDIAN(Loan_Data!I2:I615)} -> 128
A2: Gender | B2: =COUNTBLANK(Loan_Data!B2:B615) -> 0 | C2: {=INDEX(Loan_Data!C2:C615,MATCH(MAX(COUNTIF(Loan_Data!C2:C615,Loan_Data!C2:C615)),COUNTIF(Loan_Data!C2:C615,Loan_Data!C2:C615),0))} -> Yes | D2: {=MEDIAN(Loan_Data!J2:J615)} -> 360
A3: Married | B3: =COUNTBLANK(Loan_Data!C2:C615) -> 0 | C3: {=INDEX(Loan_Data!D2:D615,MATCH(MAX(COUNTIF(Loan_Data!D2:D615,Loan_Data!D2:D615)),COUNTIF(Loan_Data!D2:D615,Loan_Data!D2:D615),0))} -> 0 | D3: {=INDEX(Loan_Data!K2:K615,MATCH(MAX(COUNTIF(Loan_Data!K2:K615,Loan_Data!K2:K615)),COUNTIF(Loan_Data!K2:K615,Loan_Data!K2:K615),0))} -> 1
A4: Dependents | B4: =COUNTBLANK(Loan_Data!D2:D615) -> 0
A5: Self_Employed | B5: =COUNTBLANK(Loan_Data!G2:G615) -> 0
A6: LoanAmount | B6: =COUNTBLANK(Loan_Data!I2:I615) -> 0
A7: Loan_Amount_Term | B7: =COUNTBLANK(Loan_Data!J2:J615) -> 0
A8: Credit_History | B8: =COUNTBLANK(Loan_Data!K2:K615) -> 0

Sheet KPIs
A1: Total Applications | B1: {=COUNTA(Loan_Data!A2:A615)} -> 614
A2: Total Applroved | B2: {=COUNTIF(Loan_Data!M2:M615, "Y")} -> 422
A3: Total Rejected | B3: {=COUNTIF(Loan_Data!M2:M615,"N")} -> 192
A4: Approval Rate % | B4: {=B2/B1*100} -> 68.729642
A5: Avg Loan Amount | B5: {=AVERAGE(Loan_Data!I2:I615)} -> 145.75244
A6: Avg Applicant Income | B6: {=AVERAGE(Loan_Data!G2:G615)} -> 5403.4593
A7: Good Credit History % | B7: {=COUNTIF(Loan_Data!K2:K615,1)/B1*100} -> 85.504886
A8: Self Employed % | B8: {=COUNTIF(Loan_Data!F2:F615,"Yes")/B1*100} -> 13.355049

Sheet Pivot_Analysis
A1: Count of Loan_ID | B1: Column Labels | F1: Row Labels | G1: Average of LoanAmount | K1: Row Labels | L1: Average of Total_Income
A2: Row Labels | B2: N | C2: Y | D2: Grand Total | F2: Rural | G2: 151.44693 | K2: Approved | L2: 6888.5851
A3: Graduate | B3: 140 | C3: 340 | D3: 480 | F3: Semiurban | G3: 145.12876 | K3: Rejected | L3: 7323.8854
A4: Not Graduate | B4: 52 | C4: 82 | D4: 134 | F4: Urban | G4: 141.42574 | K4: Grand Total | L4: 7024.7051
A5: Grand Total | B5: 192 | C5: 422 | D5: 614 | F5: Grand Total | G5: 145.75244
A8: Count of Loan_ID | B8: Column Labels | F8: Count of Loan_ID | G8: Column Labels
A9: Row Labels | B9: N | C9: Y | D9: Grand Total | F9: Row Labels | G9: N | H9: Y | I9: Grand Total
A10: Rural | B10: 69 | C10: 110 | D10: 179 | F10: 0 | G10: 82 | H10: 7 | I10: 89
A11: Semiurban | B11: 54 | C11: 179 | D11: 233 | F11: 1 | G11: 110 | H11: 415 | I11: 525
A12: Urban | B12: 69 | C12: 133 | D12: 202 | F12: Grand Total | G12: 192 | H12: 422 | I12: 614
A13: Grand Total | B13: 192 | C13: 422 | D13: 614
